Workbook

Sheet 9月サマリー
B2: 9月サマリー｜コーデ+TREEBATON ＋ 建築
B3: 2026/09/01 → 09/28 のSF商談変更履歴405件を再生 ／ 単位：千円 ／ 玉＝フェーズ≠00_失注 かつ 完了予定日が26年度内の金額 ／ OEM・その他は対象外
B5: ① ABCD総玉
B6: 対象：コーデ+TREEBATON（通期26年度）。AB玉・CD玉・長期玉の合計です。
B7: 9/1 時点 | E7: 9月末 時点 | H7: 増減 | K7: 増減率
B8: =グラフ用データ!E5 -> 269603 | E8: =グラフ用データ!E6 -> 283418 | H8: =グラフ用データ!E7 -> 13815 | K8: =グラフ用データ!E7/グラフ用データ!E5 -> 0.051242011
B9: 9月末 − 9月の増減 で逆算 | E9: 10/5 SFスナップショット | H9: 9月の純増 | K9: 9/1時点に対して
B11: 内訳：AB玉 と CD玉 のどちらが動いたか
B12: AB玉 増減 | E12: CD玉 増減 | H12: 長期玉 増減 | K12: 総玉に占めるAB玉の増減
B13: =グラフ用データ!B7 -> 13841 | E13: =グラフ用データ!C7 -> -26 | H13: =グラフ用データ!D7 -> 0 | K13: =グラフ用データ!B7/グラフ用データ!E7 -> 1.001882
B14: 確度A・Bの玉 | E14: 確度C・Dの玉 | H14: 動きなし | K14: 総玉の増加はほぼAB玉
B31: 総玉は +13,815 増えましたが、CD玉はほぼ横ばい。増えたのはAB玉だけです。
B33: ② AB玉
B34: 確度A・Bの玉。成約済みも含みます。
B35: 9/1 時点 | E35: 9月末 時点 | H35: 増減 | K35: 増減率
B36: =グラフ用データ!B5 -> 85477 | E36: =グラフ用データ!B6 -> 99318 | H36: =グラフ用データ!B7 -> 13841 | K36: =グラフ用データ!B7/グラフ用データ!B5 -> 0.1619266
B37: 9月末 − 9月の増減 で逆算 | E37: =121&"件" -> 121件 | H37: 9月の純増 | K37: 9/1時点に対して
B39: なぜ増減したのか
B40: 確度UP（CD→AB） | D40: 新規作成 | F40: 失注から復活 | H40: 増額 | J40: 減額
B41: =SUMIFS('AB玉 増減明細'!$E$4:$E$23,'AB玉 増減明細'!$F$4:$F$23,"確度UP（CD→AB）",'AB玉 増減明細'!$A$4:$A$23,"コーデ+TREEBATON") -> 11696 | D41: =SUMIFS('AB玉 増減明細'!$E$4:$E$23,'AB玉 増減明細'!$F$4:$F$23,"新規作成",'AB玉 増減明細'!$A$4:$A$23,"コーデ+TREEBATON") -> 1929 | F41: =SUMIFS('AB玉 増減明細'!$E$4:$E$23,'AB玉 増減明細'!$F$4:$F$23,"失注から復活",'AB玉 増減明細'!$A$4:$A$23,"コーデ+TREEBATON") -> 220 | H41: =SUMIFS('AB玉 増減明細'!$E$4:$E$23,'AB玉 増減明細'!$F$4:$F$23,"増額",'AB玉 増減明細'!$A$4:$A$23,"コーデ+TREEBATON") -> 46 | J41: =SUMIFS('AB玉 増減明細'!$E$4:$E$23,'AB玉 増減明細'!$F$4:$F$23,"減額",'AB玉 増減明細'!$A$4:$A$23,"コーデ+TREEBATON") -> -50
B42: =COUNTIFS('AB玉 増減明細'!$F$4:$F$23,"確度UP（CD→AB）",'AB玉 増減明細'!$A$4:$A$23,"コーデ+TREEBATON")&"件" -> 5件 | D42: =COUNTIFS('AB玉 増減明細'!$F$4:$F$23,"新規作成",'AB玉 増減明細'!$A$4:$A$23,"コーデ+TREEBATON")&"件" -> 11件 | F42: =COUNTIFS('AB玉 増減明細'!$F$4:$F$23,"失注から復活",'AB玉 増減明細'!$A$4:$A$23,"コーデ+TREEBATON")&"件" -> 1件 | H42: =COUNTIFS('AB玉 増減明細'!$F$4:$F$23,"増額",'AB玉 増減明細'!$A$4:$A$23,"コーデ+TREEBATON")&"件" -> 1件 | J42: =COUNTIFS('AB玉 増減明細'!$F$4:$F$23,"減額",'AB玉 増減明細'!$A$4:$A$23,"コーデ+TREEBATON")&"件" -> 1件
B59: 増加の84%が「確度UP」。うち認証桧柾目材供給PJの2件で +10,616、確度UP全体の91%を占めます。
B60: 確度UPでCD玉から出たのは -5,152。AB玉には +11,696 入りました。差の +6,544 は、確度が上がると同時に金額が増えたぶんです。
B62: ③ CD玉
B63: 確度C・Dの玉。来月以降にAB玉へ上げられるストックです。
B64: 9/1 時点 | E64: 9月末 時点 | H64: 増減 | K64: 増減率
B65: =グラフ用データ!C5 -> 183826 | E65: =グラフ用データ!C6 -> 183800 | H65: =グラフ用データ!C7 -> -26 | K65: =グラフ用データ!C7/グラフ用データ!C5 -> -0.0001414381
B66: 9月末 − 9月の増減 で逆算 | E66: =113&"件" -> 113件 | H66: ほぼ横ばい | K66: 9/1時点に対して
B68: なぜ増減したのか
B69: 新規作成 | D69: 増額 | F69: 確度UP（AB玉へ移動） | H69: 失注 | J69: 減額
B70: =SUMIFS('CD玉 増減明細'!$E$4:$E$25,'CD玉 増減明細'!$F$4:$F$25,"新規作成",'CD玉 増減明細'!$A$4:$A$25,"コーデ+TREEBATON") -> 6904 | D70: =SUMIFS('CD玉 増減明細'!$E$4:$E$25,'CD玉 増減明細'!$F$4:$F$25,"増額",'CD玉 増減明細'!$A$4:$A$25,"コーデ+TREEBATON") -> 3855 | F70: =SUMIFS('CD玉 増減明細'!$E$4:$E$25,'CD玉 増減明細'!$F$4:$F$25,"確度UP（CD→AB）",'CD玉 増減明細'!$A$4:$A$25,"コーデ+TREEBATON") -> -5152 | H70: =SUMIFS('CD玉 増減明細'!$E$4:$E$25,'CD玉 増減明細'!$F$4:$F$25,"失注",'CD玉 増減明細'!$A$4:$A$25,"コーデ+TREEBATON") -> -5597 | J70: =SUMIFS('CD玉 増減明細'!$E$4:$E$25,'CD玉 増減明細'!$F$4:$F$25,"減額",'CD玉 増減明細'!$A$4:$A$25,"コーデ+TREEBATON") -> -36
B71: =COUNTIFS('CD玉 増減明細'!$F$4:$F$25,"新規作成",'CD玉 増減明細'!$A$4:$A$25,"コーデ+TREEBATON")&"件" -> 7件 | D71: =COUNTIFS('CD玉 増減明細'!$F$4:$F$25,"増額",'CD玉 増減明細'!$A$4:$A$25,"コーデ+TREEBATON")&"件" -> 4件 | F71: =COUNTIFS('CD玉 増減明細'!$F$4:$F$25,"確度UP（CD→AB）",'CD玉 増減明細'!$A$4:$A$25,"コーデ+TREEBATON")&"件" -> 4件 | H71: =COUNTIFS('CD玉 増減明細'!$F$4:$F$25,"失注",'CD玉 増減明細'!$A$4:$A$25,"コーデ+TREEBATON")&"件" -> 6件 | J71: =COUNTIFS('CD玉 増減明細'!$F$4:$F$25,"減額",'CD玉 増減明細'!$A$4:$A$25,"コーデ+TREEBATON")&"件" -> 1件
B88: 新規 +6,904 と 増額 +3,855 で積み上げた分を、確度UPでの流出 -5,152 と 失注 -5,597 がほぼ打ち消しました。
B89: 結果としてCD玉は横ばい。来月以降に確度を上げられる玉のストックは増えていません。
B91: ④ 9月の動き
B92: 成約・新規作成・失注。明細は各シートにあります。
B93: 成約 | E93: 新規作成 | H93: 失注 | K93: 新規のうち金額未入力
B94: =SUM(成約明細!$C$4:$C$16) -> 14382 | E94: =SUM(新規作成明細!$C$4:$C$41) -> 9345 | H94: =-SUM(失注明細!$C$4:$C$12) -> -5597 | K94: =COUNTIF(新規作成明細!$G$4:$G$41,"●") -> 18
B95: =13&"件" -> 13件 | E95: =38&"件" -> 38件 | H95: =9&"件。すべて確度C・D" -> 9件。すべて確度C・D | K95: ="件。新規"&38&"件の"&TEXT(COUNTIF(新規作成明細!$G$4:$G$41,"●")/38,"0.0%") -> 件。新規38件の47.4%
B97: ⑤ 建築
...

Sheet Sheet

Sheet AB玉 増減明細
A1: AB玉が動いた案件（9/1 → 9月末）
A2: AB玉＝確度A・B かつ フェーズ≠00_失注 かつ 完了予定日が26年度内の金額。単位：千円。
A3: グループ | B3: 商談名 | C3: 9/1 AB玉 | D3: 9月末 AB玉 | E3: 増減 | F3: 理由 | G3: 9/1 確度 | H3: 9月末 確度
A4: コーデ+TREEBATON | B4: 子商談_認証桧柾目材供給PJ_3回目(FSC尾鷲) | C4: 0 | D4: 7616 | E4: 7616 | F4: 確度UP（CD→AB） | G4: C | H4: B
A5: コーデ+TREEBATON | B5: 子商談_認証桧柾目材供給PJ_2回目(SGEC富士市) | C5: 0 | D5: 3000 | E5: 3000 | F5: 確度UP（CD→AB） | G5: C | H5: A
A6: コーデ+TREEBATON | B6: ERIKOYAMAGUCHI_名古屋 | C6: 0 | D6: 1128 | E6: 1128 | F6: 新規作成 | G6: （新規） | H6: B
A7: コーデ+TREEBATON | B7: 御殿場KEEN店舗_カウンター用静岡県産半割丸太 | C7: 0 | D7: 500 | E7: 500 | F7: 確度UP（CD→AB） | G7: C | H7: B
A8: 建築 | B8: 枠材製作（材工）モックアップ製作 | C8: 0 | D8: 462 | E8: 462 | F8: 新規作成 | G8: （新規） | H8: A
A9: コーデ+TREEBATON | B9: TREホールディングス_丸太輪切り材 | C9: 0 | D9: 430 | E9: 430 | F9: 確度UP（CD→AB） | G9: C | H9: A
A10: コーデ+TREEBATON | B10: 習志野カントリークラブ_VIPルーム黒柿 | C10: 0 | D10: 220 | E10: 220 | F10: 失注から復活 | G10: D | H10: B
A11: コーデ+TREEBATON | B11: 水戸京成RLC | C11: 0 | D11: 173 | E11: 173 | F11: 新規作成 | G11: （新規） | H11: A
A12: コーデ+TREEBATON | B12: ロイヤルHD本社工場直販店(福岡)_既存樹活用（引上げ・製材・乾燥） | C12: 0 | D12: 150 | E12: 150 | F12: 確度UP（CD→AB） | G12: C | H12: B
A13: コーデ+TREEBATON | B13: 内閣府用木札_2026 | C13: 0 | D13: 149 | E13: 149 | F13: 新規作成 | G13: （新規） | H13: A
A14: コーデ+TREEBATON | B14: 外装用焼杉（羽目板） | C14: 0 | D14: 120 | E14: 120 | F14: 新規作成 | G14: （新規） | H14: A
A15: コーデ+TREEBATON | B15: クリ巾ハギ材（小）_260924分_発注No.PD-820 | C15: 0 | D15: 98 | E15: 98 | F15: 新規作成 | G15: （新規） | H15: A
... A23: コーデ+TREEBATON | B23: 26年度_千本松牧場PJ_⑤記念品製造／バードコール＆写真フレーム | C23: 2000 | D23: 1950 | E23: -50 | F23: 減額 | G23: B | H23: A

Sheet CD玉 増減明細
A1: CD玉が動いた案件（9/1 → 9月末）
A2: CD玉＝確度C・D かつ フェーズ≠00_失注 かつ 完了予定日が26年度内の金額。「確度UP（CD→AB）」はAB玉へ移ったぶんです。単位：千円。
A3: グループ | B3: 商談名 | C3: 9/1 CD玉 | D3: 9月末 CD玉 | E3: 増減 | F3: 理由 | G3: 9/1 確度 | H3: 9月末 確度
A4: コーデ+TREEBATON | B4: 子商談_認証桧柾目材供給PJ_4回目(SGEC富士市) | C4: 0 | D4: 5834 | E4: 5834 | F4: 新規作成 | G4: （新規） | H4: C
A5: コーデ+TREEBATON | B5: 高島屋SC_船橋研修施設_床材 | C5: 0 | D5: 1649 | E5: 1649 | F5: 増額 | G5: D | H5: D
A6: コーデ+TREEBATON | B6: 森林の仕事Park(なんば)_森の体感ブース設営R8 | C6: 1000 | D6: 2500 | E6: 1500 | F6: 増額 | G6: C | H6: C
A7: コーデ+TREEBATON | B7: ららぽーとTOKYO-BAY_ヤシの木_既存樹利用_本番 | C7: 0 | D7: 376 | E7: 376 | F7: 増額 | G7: C | H7: C
A8: コーデ+TREEBATON | B8: 3Dベンチ_展示品 | C8: 0 | D8: 360 | E8: 360 | F8: 新規作成 | G8: （新規） | H8: C
A9: コーデ+TREEBATON | B9: 島根県東津田PJ | C9: 920 | D9: 1250 | E9: 330 | F9: 増額 | G9: C | H9: C
A10: コーデ+TREEBATON | B10: HOTEL THE MITSUI_補修_10月 | C10: 0 | D10: 265 | E10: 265 | F10: 新規作成 | G10: （新規） | H10: C
A11: コーデ+TREEBATON | B11: 茨城県産材利用_某案件 | C11: 0 | D11: 235 | E11: 235 | F11: 新規作成 | G11: （新規） | H11: C
A12: コーデ+TREEBATON | B12: 銀座ミキモト_ドアハンドル | C12: 0 | D12: 120 | E12: 120 | F12: 新規作成 | G12: （新規） | H12: C
A13: コーデ+TREEBATON | B13: （仮称）ファインコート三鷹_三井不社有林利用_図面およびモックアップ作成フェーズ | C13: 0 | D13: 80 | E13: 80 | F13: 新規作成 | G13: （新規） | H13: C
A14: コーデ+TREEBATON | B14: 味の素本社_アジパンダショップ_プライスカード立て（追加） | C14: 0 | D14: 10 | E14: 10 | F14: 新規作成 | G14: （新規） | H14: C
A15: コーデ+TREEBATON | B15: スターバックスロースタリー中目黒_プライスカード立て | C15: 106 | D15: 70 | E15: -36 | F15: 減額 | G15: C | H15: C
... A25: コーデ+TREEBATON | B25: 子商談_認証桧柾目材供給PJ_2回目(SGEC富士市) | C25: 3352 | D25: 0 | E25: -3352 | F25: 確度UP（CD→AB） | G25: C | H25: A

Sheet 成約明細
A1: 9月に成約した案件（フェーズ → 07.成約）
A2: 対象：コーデ+TREEBATON ／ 建築。単位：千円。
A3: グループ | B3: 商談名 | C3: 金額 | D3: 変更前フェーズ | E3: 完了予定日
A4: コーデ+TREEBATON | B4: アルジェニクスジャパン_オフィス家具 | C4: 3640 | D4: 01.商談化 | E4: 2026/12/30
A5: コーデ+TREEBATON | B5: 子商談_認証桧柾目材供給PJ_2回目(SGEC富士市) | C5: 3000 | D5: 01.商談化 | E5: 2026/09/02
A6: コーデ+TREEBATON | B6: 26年度_千本松牧場PJ_④小サイン・林内ベンチ製造 | C6: 3000 | D6: 06.契約手続き中 | E6: 2026/09/11
A7: コーデ+TREEBATON | B7: 26年度_千本松牧場PJ_⑤記念品製造／バードコール＆写真フレーム | C7: 1950 | D7: 06.契約手続き中 | E7: 2026/09/11
A8: コーデ+TREEBATON | B8: ホウライ様予算_26年度_千本松牧場PJ_林内ベンチ製造 | C8: 1384 | D8: 06.契約手続き中 | E8: 2026/09/03
A9: 建築 | B9: CLT試験材 | C9: 535 | D9: 06.契約手続き中 | E9: 2026/09/30
A10: コーデ+TREEBATON | B10: TREホールディングス_丸太輪切り材 | C10: 430 | D10: 01.商談化 | E10: 2026/08/08
A11: コーデ+TREEBATON | B11: 内閣府用木札_2026 | C11: 149 | D11: 01.商談化 | E11: 2026/09/28
A12: コーデ+TREEBATON | B12: 外装用焼杉（羽目板） | C12: 120 | D12: 01.商談化 | E12: 2026/10/02
A13: コーデ+TREEBATON | B13: 味の素本社_レストランフロア壁面オブジェ（追加作業） | C13: 62 | D13: 01.商談化 | E13: 2026/09/30
A14: コーデ+TREEBATON | B14: ウッドチップ | C14: 62 | D14: 01.商談化 | E14: 2026/09/25
A15: コーデ+TREEBATON | B15: 日建設計×乃村工藝社_間伐材利用某サーキュラー案件_試作用ecoシラ合板 | C15: 38 | D15: 01.商談化 | E15: 2026/09/15
A16: コーデ+TREEBATON | B16: 藍建材サンプル | C16: 12 | D16: 06.契約手続き中 | E16: 2026/09/24

Sheet 新規作成明細
A1: 9月に新規作成された商談
A2: 対象：コーデ+TREEBATON ／ 建築。単位：千円。「金額未入力」は見込みに乗っていない案件です。
A3: グループ | B3: 商談名 | C3: 金額 | D3: 確度 | E3: フェーズ | F3: 完了予定 | G3: 金額未入力
A4: コーデ+TREEBATON | B4: 子商談_認証桧柾目材供給PJ_4回目(SGEC富士市) | C4: 5834 | D4: C | E4: 01.商談化 | F4: 2026/12
A5: コーデ+TREEBATON | B5: ERIKOYAMAGUCHI_名古屋 | C5: 1128 | D5: B | E5: 01.商談化 | F5: 2027/03
A6: 建築 | B6: 枠材製作（材工）モックアップ製作 | C6: 462 | D6: A | E6: 01.商談化 | F6: 2026/11
A7: コーデ+TREEBATON | B7: 3Dベンチ_展示品 | C7: 360 | D7: C | E7: 01.商談化 | F7: 2026/12
A8: コーデ+TREEBATON | B8: HOTEL THE MITSUI_補修_10月 | C8: 265 | D8: C | E8: 05.施工調整 | F8: 2026/10
A9: コーデ+TREEBATON | B9: 茨城県産材利用_某案件 | C9: 235 | D9: C | E9: 01.商談化 | F9: 2026/10
A10: コーデ+TREEBATON | B10: 水戸京成RLC | C10: 173 | D10: A | E10: 01.商談化 | F10: 2026/09
A11: コーデ+TREEBATON | B11: 内閣府用木札_2026 | C11: 149 | D11: A | E11: 07.成約 | F11: 2026/09
A12: コーデ+TREEBATON | B12: 外装用焼杉（羽目板） | C12: 120 | D12: A | E12: 07.成約 | F12: 2026/10
A13: コーデ+TREEBATON | B13: 銀座ミキモト_ドアハンドル | C13: 120 | D13: C | E13: 01.商談化 | F13: 2026/10
A14: コーデ+TREEBATON | B14: クリ巾ハギ材（小）_260924分_発注No.PD-820 | C14: 98 | D14: A | E14: 07.成約 | F14: 2026/10
A15: コーデ+TREEBATON | B15: （仮称）ファインコート三鷹_三井不社有林利用_図面およびモックアップ作成フェーズ | C15: 80 | D15: C | E15: 01.商談化 | F15: 2026/12
... A23: コーデ+TREEBATON | B23: 味の素本社_アジパンダショップ_プライスカード立て（追加） | C23: 10 | D23: C | E23: 06.契約手続き中 | F23: 2026/10
A24: コーデ+TREEBATON | B24: サミット本社ビル1階改装 | C24: 0 | D24: D | E24: 01.商談化 | F24: 2027/03 | G24: ●
A25: コーデ+TREEBATON | B25: ラーメン店_間仕切壁_不燃木材提案 | C25: 0 | D25: D | E25: 01.商談化 | F25: 2030/03 | G25: ●
A26: コーデ+TREEBATON | B26: 池田山_既存樹アートオブジェ | C26: 0 | D26: C | E26: 01.商談化 | F26: 2026/10 | G26: ●
A27: コーデ+TREEBATON | B27: 三井不動産レジデンシャル_ChopValue加工 | C27: 0 | D27: D | E27: 01.商談化 | F27: 2028/01 | G27: ●
A28: コーデ+TREEBATON | B28: Fujitsu Technology Parkプロジェクト_既存樹活用（製作フェーズ） | C28: 0 | D28: C | E28: 01.商談化 | F28: 2028/08 | G28: ●
A29: コーデ+TREEBATON | B29: 花博_日比谷花壇ブース_ベンチ兼テーブル | C29: 0 | D29: D | E29: 01.商談化 | F29: 2027/03 | G29: ●
A30: コーデ+TREEBATON | B30: 多摩産材_飲食店カラトリ―什器 | C30: 0 | D30: D | E30: 01.商談化 | F30: 2026/11 | G30: ●
A31: コーデ+TREEBATON | B31: 藍建材羽目板 | C31: 0 | D31: C | E31: 01.商談化 | F31: 2027/02 | G31: ●
A32: コーデ+TREEBATON | B32: 既存樹余り材活用プロジェクト | C32: 0 | D32: C | E32: 01.商談化 | F32: 2027/06 | G32: ●
A33: コーデ+TREEBATON | B33: 世田谷飲食店_VE提案壁材 | C33: 0 | D33: D | E33: 02.提案 | F33: 2026/12 | G33: ●
A34: コーデ+TREEBATON | B34: 秋田県産ドアハンドル | C34: 0 | D34: D | E34: 01.商談化 | F34: 2026/10 | G34: ●
A35: コーデ+TREEBATON | B35: ホウライ様100周年記念品 | C35: 0 | D35: C | E35: 01.商談化 | F35: 2027/09 | G35: ●
... A41: コーデ+TREEBATON | B41: 千葉県商業施設改装_不燃木材 | C41: 0 | D41: D | E41: 01.商談化 | F41: 2027/07 | G41: ●

Sheet 失注明細
A1: 9月に失注した案件
A2: 対象：コーデ+TREEBATON ／ 建築。単位：千円。いずれも確度C・DのためAB玉への影響はありません。
A3: グループ | B3: 商談名 | C3: 金額 | D3: 確度 | E3: 失注前フェーズ
A4: コーデ+TREEBATON | B4: 都内タワーマンションフローリング | C4: 1572 | D4: C | E4: 01.商談化
A5: コーデ+TREEBATON | B5: 沖縄県産材_椅子製作 | C5: 1300 | D5: D | E5: 01.商談化
A6: コーデ+TREEBATON | B6: 東急HVC草津_FF&E | C6: 1000 | D6: C | E6: 02.提案
A7: コーデ+TREEBATON | B7: 光円寺 寺院古材活用に向けた地蔵堂解体工事 | C7: 800 | D7: C | E7: 01.商談化
A8: コーデ+TREEBATON | B8: 霞が関PJ | C8: 785 | D8: C | E8: 01.商談化
A9: コーデ+TREEBATON | B9: LINA WOOD_ナラ | C9: 140 | D9: C | E9: 05.施工調整
A10: コーデ+TREEBATON | B10: 造作家具用_国産合板 | C10: 0 | D10: C | E10: 01.商談化
A11: コーデ+TREEBATON | B11: 群馬ホテルリノベーション_なぐりフローリング特注色 | C11: 0 | D11: C | E11: 02.提案
A12: コーデ+TREEBATON | B12: カトリック上野教会_Emma | C12: 0 | D12: C | E12: 01.商談化

Sheet グラフ用データ
A1: グラフ用データ（サマリーのグラフが参照します）
A2: 青字＝SFスナップショットからの入力。黒字＝増減明細シートからの自動計算。単位：千円。
A4: 区分 | B4: AB玉 | C4: CD玉 | D4: 長期玉 | E4: ABCD総玉
A5: 9/1 時点 | B5: =B6-SUMIF('AB玉 増減明細'!$A$4:$A$23,"コーデ+TREEBATON",'AB玉 増減明細'!$E$4:$E$23) -> 85477 | C5: =C6-SUMIF('CD玉 増減明細'!$A$4:$A$25,"コーデ+TREEBATON",'CD玉 増減明細'!$E$4:$E$25) -> 183826 | D5: 300 | E5: =SUM(B5:D5) -> 269603
A6: 9月末 時点 | B6: 99318 | C6: 183800 | D6: 300 | E6: =SUM(B6:D6) -> 283418
A7: 増減 | B7: =B6-B5 -> 13841 | C7: =C6-C5 -> -26 | D7: =D6-D5 -> 0 | E7: =E6-E5 -> 13815
A9: AB玉 増加の内訳（プラス要因）
A10: 確度UP（CD→AB） | B10: =SUMIFS('AB玉 増減明細'!$E$4:$E$23,'AB玉 増減明細'!$F$4:$F$23,"確度UP（CD→AB）",'AB玉 増減明細'!$A$4:$A$23,"コーデ+TREEBATON") -> 11696
A11: 新規作成 | B11: =SUMIFS('AB玉 増減明細'!$E$4:$E$23,'AB玉 増減明細'!$F$4:$F$23,"新規作成",'AB玉 増減明細'!$A$4:$A$23,"コーデ+TREEBATON") -> 1929
A12: その他（失注から復活＋増額） | B12: =SUMIFS('AB玉 増減明細'!$E$4:$E$23,'AB玉 増減明細'!$F$4:$F$23,"失注から復活",'AB玉 増減明細'!$A$4:$A$23,"コーデ+TREEBATON")+SUMIFS('AB玉 増減明細'!$E$4:$E$23,'AB玉 増減明細'!$F$4:$F$23,"増額",'AB玉 増減明細'!$A$4:$A$23,"コーデ+TREEBATON") -> 266
A13: （参考）減額 | B13: =SUMIFS('AB玉 増減明細'!$E$4:$E$23,'AB玉 増減明細'!$F$4:$F$23,"減額",'AB玉 増減明細'!$A$4:$A$23,"コーデ+TREEBATON") -> -50
A16: CD玉 増加要因
A17: 新規作成 | B17: =SUMIFS('CD玉 増減明細'!$E$4:$E$25,'CD玉 増減明細'!$F$4:$F$25,"新規作成",'CD玉 増減明細'!$A$4:$A$25,"コーデ+TREEBATON") -> 6904
A18: 増額 | B18: =SUMIFS('CD玉 増減明細'!$E$4:$E$25,'CD玉 増減明細'!$F$4:$F$25,"増額",'CD玉 増減明細'!$A$4:$A$25,"コーデ+TREEBATON") -> 3855
A20: CD玉 減少要因（絶対値）
A21: 失注 | B21: =ABS(SUMIFS('CD玉 増減明細'!$E$4:$E$25,'CD玉 増減明細'!$F$4:$F$25,"失注",'CD玉 増減明細'!$A$4:$A$25,"コーデ+TREEBATON")) -> 5597
A22: 確度UP（AB玉へ移動） | B22: =ABS(SUMIFS('CD玉 増減明細'!$E$4:$E$25,'CD玉 増減明細'!$F$4:$F$25,"確度UP（CD→AB）",'CD玉 増減明細'!$A$4:$A$25,"コーデ+TREEBATON")) -> 5152
A23: 減額 | B23: =ABS(SUMIFS('CD玉 増減明細'!$E$4:$E$25,'CD玉 増減明細'!$F$4:$F$25,"減額",'CD玉 増減明細'!$A$4:$A$25,"コーデ+TREEBATON")) -> 36

Sheet 算出方法
A1: 算出方法と注意点
A3: ■ 対象
A4: レコードタイプ | B4: 木材コーディネート／TREEBATON／建築案件。OEM・森林認証コンサル・受託事業は対象外
A5: 期間 | B5: 2026/09/01 10:26 〜 2026/09/28 15:37。9/29・9/30の動きは含まれていません
A6: 除外 | B6: ＊原価管理用＊ を含む商談
A8: ■ 定義
A9: ABCD総玉 | B9: AB玉 ＋ CD玉 ＋ 長期玉。フェーズ≠00_失注 かつ 完了予定日が26年度（2026/04/01〜2027/03/31）内
A10: AB玉 | B10: 確度A・B。成約済み（フェーズ07）も含む
A11: CD玉 | B11: 確度C・D
A12: 長期玉 | B12: 確度「長期」。9月は動きなし（300千円）
A13: 確度UP（CD→AB） | B13: 9/1はC・D、9月末はA・Bになったもの。CD玉からは減り、AB玉には増える
A15: ■ 数字の作り方
A16: 9月末 時点 | B16: 2026/10/05 のSFスナップショット（★コーデTB_総商談_通期_26年度 235件）。9/29〜10/5の変更は未取得のため同じとみなしています
A17: 9/1 時点 | B17: 9月末 時点 − 9月の増減 で逆算
A18: 9月の増減 | B18: SFの商談変更履歴3本（09/01-09/08／09/08-09/14／09/14-09/28）405件を時系列で再生
A19: 9/1時点の各項目 | B19: 現在値から変更チェーンを逆向きに辿って復元（元の値→新しい値のループに対応）
A20: 重複 | B20: ファイル間で重なる期間の同一変更は除外済み
A22: ■ グラフ
A23: 配色 | B23: 色覚多様性に配慮した5色（CVD分離 ΔE 12.9 で検証済み）。すべてのグラフにデータラベルを表示
A24: 参照先 | B24: 「グラフ用データ」シート。増減明細シートから自動計算されます
A26: ■ 注意点
A27: 建築の絶対値 | B27: ★コーデTBレポートに含まれないため未取得。建築の通期レポートがあれば同じ形で出せます
A28: 9/29・9/30 | B28: 変更履歴が未取得。厳密には「9/28時点」です
A29: 金額未入力 | B29: 新規38件のうち18件（47%）が金額0。見込みに乗っていない
A30: 集中度 | B30: 確度UPの91%が認証桧柾目材供給PJ（2回目＋3回目）の2件／成約の44%が千本松牧場PJの3件
A31: ATONA_京都_FFE | B31: 9月中に金額が0と5,900,000の間を何度も往復。9/1と9月末で同額のため増減ゼロとして扱った
