Workbook

Sheet ダッシュボード
B2: 森未来 営業部｜下期ダッシュボード
B3: 木材コーディネート＋TREEBATON（OEM・建築は含まず）／失注除外／2026-10-05 SF出力 単位：千円
B5: ① 下期の数字
B6: SFから集計した実数。月次シートの青字を更新すると、このページも自動で変わります。
B7: 下期予算 | E7: ① 受注済（成約） | H7: ② AB玉 | K7: ③ CD玉（在庫）
B8: =前提!B7 -> 141913 | E8: =月次!H7 -> 13111 | H8: =月次!H8 -> 20739 | K8: =月次!H12 -> 183799
B9: ※ 9/11時点の値・要確認 | E9: フェーズ07.成約 8件 | H9: 確度A・B／未成約 12件 | K9: 確度C・D／未成約 113件
B11: ② ほぼ動かない確定ライン
B12: AB玉までは確度が高い。残りをCD玉から作れるかが下期のすべてです。
B13: AB玉ベース着地見込み | E13: 下期予算に対する達成率 | H13: 残り必要額 | K13: 必要転換率
B14: =月次!H9 -> 33850 | E14: =月次!H10 -> 0.23852642 | H14: =月次!H11 -> 108063 | K14: =月次!H13 -> 0.58794117
B15: ① ＋ ② | E15: AB玉ベース着地 ÷ 下期予算 | H15: 下期予算 −① −② | K15: 残り必要額 ÷ CD玉。これだけ転換できれば予算に届く
B17: ③ 最終着地の見込み
B18: CD玉を実績どおりの成約率で落とした場合の着地です。
B19: 実績の成約率 | E19: CD玉からの転換額 | H19: 最終着地見込み | K19: 下期予算との差
B20: =前提!B9 -> 0.373 | E20: =月次!H14 -> 68557.027 | H20: =月次!H15 -> 102407.03 | K20: =月次!H17 -> -39505.973
B21: 直近2年593件の実測 | E21: CD玉 × 実績の成約率 | H21: ① ＋ ② ＋ 転換額 | K21: 下期予算 − 最終着地見込み
B22: 必要転換率 58.8% に対して実績は 37.3%。21.5ポイント足りません。
B24: ④ 月別の着地率
B25: 月予算は下期予算の均等割です。100%を超えていれば月予算に届く見込み。
B26: 10月 | E26: 11月 | H26: 12月 | K26: 下期 6ヶ月
B27: =月次!B16 -> 1.1229386 | E27: =月次!C16 -> 0.25294765 | H27: =月次!D16 -> 0.92961885 | K27: =月次!H16 -> 0.72161836
B28: 着地26,560 ／ 月予算23,652 | E28: 着地5,983 ／ 月予算23,652 | H28: 着地21,988 ／ 月予算23,652 | K28: 着地102,407 ／ 下期予算141,913
B30: 10月の過不足 | E30: 11月の過不足 | H30: 12月の過不足 | K30: 3月に寄っている玉
B31: =月次!B17 -> 2907.7643 | E31: =月次!C17 -> -17669.407 | H31: =月次!D17 -> -1664.6667 | K31: =月次!G12 -> 118674
B32: 月予算との差 | E32: 月予算との差 | H32: 月予算との差 | K32: CD玉の65%が3月完了予定
B34: 11月は玉が9件・9,820千円しかありません。必要転換率326%＝いまの玉では月予算に届きません。
B36: ⑤ 9月に起きたこと（AB総玉の増減）
B37: 2026/09/01 〜 09/28 のSF変更履歴405件を再生。9/29・9/30は含みません。
B38: 全社 AB総玉 | E38: コーデ+TREEBATON | H38: 建築 | K38: その他
B39: =月次増減!C10 -> 12004 | E39: =月次増減!C6 -> 13842 | H39: =月次増減!C7 -> 462 | K39: =月次増減!C9 -> -2300
B40: 9/1 → 9/28 の純増 | E40: 最大の増加要因 | H40: 枠材製作モックアップの新規 | K40: FM_フルサポートの期ズレ
B42: 確度UPによる増加 | E42: 新規作成による増加 | H42: 9月の成約 | K42: 9月の失注
B43: =月次増減!C14 -> 11896 | E43: =月次増減!C15 -> 2391 | H43: =月次増減!C22 -> 17383 | K43: 10
B44: 6件。AB総玉増加の99% | E44: 12件のみAB玉に乗った | H44: 14件 | K44: 件。すべて確度C・DのためAB玉に影響なし
B46: 増加の99%が「確度UP」。うち89%が認証桧柾目材供給PJ（2回目＋3回目）の2件に集中しています。
B48: ⑥ 着地シミュレーション（黄色だけ編集）
B49: 転換率を上げたら、金額未入力を埋めたら、着地はどうなるか。黄色のセルを変えると下の数字が動きます。
B50: 【入力】想定する転換率 | E50: 【入力】未入力34件の単価 | H50: 補完後のCD玉 | K50: シミュ後の転換額
B51: 0.373 | E51: 0 | H51: =月次!H12+前提!B10*E51 -> 183799 | K51: =H51*B51 -> 68557.027
...

Sheet 前提
A1: 前提（入力値）
A2: スコープ | B2: 木材コーディネート＋TREEBATON／フェーズ00_失注を除外／OEM・建築は含まない
A3: データ基準日 | B3: 2026/10/05 SF出力（9月増減は 09/01〜09/28 の変更履歴）
A4: 出典 | B4: ★コーデTB_総商談_通期_26年度（235件）／★コーデTB_AB_下期_26年度（20件）／商談変更履歴3本
A6: ■ ここだけ更新すれば全シートが再計算されます
A7: 下期予算（千円） | B7: 141913 | C7: ※ 9/11時点で使用した値。SFの正式な下期予算と一致するか要確認
A8: 下期の月数 | B8: 6 | C8: ※ 10月〜3月
A9: CD玉の想定転換率 | B9: 0.373 | C9: ※ 直近2年593件の実測成約率（成約件数 ÷ 総商談件数）
A10: CD玉 金額未入力 件数 | B10: 34 | C10: ※ 下期CD玉113件のうち金額が空欄のもの
A11: 入力済CD玉の中央値（千円） | B11: 1000 | C11: ※ 金額が入っている79件の中央値
A12: 入力済CD玉の平均（千円） | B12: 2327 | C12: ※ 金額が入っている79件の平均
A14: 月予算（千円） | B14: =B7/B8 -> 23652.167 | C14: ＝ 下期予算 ÷ 月数（均等割）。実際の月次配分があれば月次シートで直接上書きしてください
A17: ■ 凡例
A18: 青字 | B18: 手入力。SFレポートから転記する数字
A19: 黒字 | B19: 数式。触らない
A20: 黄色塗り | B20: 重要な前提。変わると全体が動く

Sheet 月次
A1: 月次（下期6ヶ月） 単位：千円
A2: 青字のみ手入力。SFの完了予定月・確度・フェーズで集計した値を入れてください。
A4: 項目 | B4: 10月 | C4: 11月 | D4: 12月 | E4: 1月 | F4: 2月 | G4: 3月 | H4: 下期合計
A5: 商談件数 | B5: 32 | C5: 9 | D5: 32 | E5: 4 | F5: 5 | G5: 52 | H5: =SUM(B5:G5) -> 134
A6: 月予算 | B6: =前提!$B$7/前提!$B$8 -> 23652.167 | C6: =前提!$B$7/前提!$B$8 -> 23652.167 | D6: =前提!$B$7/前提!$B$8 -> 23652.167 | E6: =前提!$B$7/前提!$B$8 -> 23652.167 | F6: =前提!$B$7/前提!$B$8 -> 23652.167 | G6: =前提!$B$7/前提!$B$8 -> 23652.167 | H6: =SUM(B6:G6) -> 141913
A7: ① 受注済（フェーズ07.成約） | B7: 9471 | C7: 0 | D7: 3640 | E7: 0 | F7: 0 | G7: 0 | H7: =SUM(B7:G7) -> 13111
A8: ② AB玉（確度A・B／未成約） | B8: 10805 | C8: 3700 | D8: 5106 | E8: 0 | F8: 0 | G8: 1128 | H8: =SUM(B8:G8) -> 20739
A9: AB玉ベース着地見込み（①＋②） | B9: =B7+B8 -> 20276 | C9: =C7+C8 -> 3700 | D9: =D7+D8 -> 8746 | E9: =E7+E8 -> 0 | F9: =F7+F8 -> 0 | G9: =G7+G8 -> 1128 | H9: =SUM(B9:G9) -> 33850
A10: 月予算に対する達成率 | B10: =IFERROR(B9/B6,"") -> 0.85725762 | C10: =IFERROR(C9/C6,"") -> 0.15643387 | D10: =IFERROR(D9/D6,"") -> 0.36977585 | E10: =IFERROR(E9/E6,"") -> 0 | F10: =IFERROR(F9/F6,"") -> 0 | G10: =IFERROR(G9/G6,"") -> 0.047691191 | H10: =IFERROR(H9/H6,"") -> 0.23852642
A11: 残り必要額（月予算 −①−②） | B11: =B6-B9 -> 3376.1667 | C11: =C6-C9 -> 19952.167 | D11: =D6-D9 -> 14906.167 | E11: =E6-E9 -> 23652.167 | F11: =F6-F9 -> 23652.167 | G11: =G6-G9 -> 22524.167 | H11: =SUM(B11:G11) -> 108063
A12: ③ CD玉（確度C・D／未成約） | B12: 16847 | C12: 6120 | D12: 35500 | E12: 3708 | F12: 2950 | G12: 118674 | H12: =SUM(B12:G12) -> 183799
A13: 必要転換率（残り必要額 ÷ CD玉） | B13: =IFERROR(B11/B12,"") -> 0.20040165 | C13: =IFERROR(C11/C12,"") -> 3.260158 | D13: =IFERROR(D11/D12,"") -> 0.41989202 | E13: =IFERROR(E11/E12,"") -> 6.3786857 | F13: =IFERROR(F11/F12,"") -> 8.0176836 | G13: =IFERROR(G11/G12,"") -> 0.18979866 | H13: =IFERROR(H11/H12,"") -> 0.58794117
A14: CD玉からの転換（想定転換率） | B14: =B12*前提!$B$9 -> 6283.931 | C14: =C12*前提!$B$9 -> 2282.76 | D14: =D12*前提!$B$9 -> 13241.5 | E14: =E12*前提!$B$9 -> 1383.084 | F14: =F12*前提!$B$9 -> 1100.35 | G14: =G12*前提!$B$9 -> 44265.402 | H14: =SUM(B14:G14) -> 68557.027
A15: 最終着地見込み（①＋②＋転換） | B15: =B9+B14 -> 26559.931 | C15: =C9+C14 -> 5982.76 | D15: =D9+D14 -> 21987.5 | E15: =E9+E14 -> 1383.084 | F15: =F9+F14 -> 1100.35 | G15: =G9+G14 -> 45393.402 | H15: =SUM(B15:G15) -> 102407.03
A16: 最終着地率 | B16: =IFERROR(B15/B6,"") -> 1.1229386 | C16: =IFERROR(C15/C6,"") -> 0.25294765 | D16: =IFERROR(D15/D6,"") -> 0.92961885 | E16: =IFERROR(E15/E6,"") -> 0.058475996 | F16: =IFERROR(F15/F6,"") -> 0.046522165 | G16: =IFERROR(G15/G6,"") -> 1.9192069 | H16: =IFERROR(H15/H6,"") -> 0.72161836
A17: 月予算に対する過不足 | B17: =B15-B6 -> 2907.7643 | C17: =C15-C6 -> -17669.407 | D17: =D15-D6 -> -1664.6667 | E17: =E15-E6 -> -22269.083 | F17: =F15-F6 -> -22551.817 | G17: =G15-G6 -> 21741.235 | H17: =SUM(B17:G17) -> -39505.973
A19: （参考）金額未入力 件数 | B19: 6 | C19: 3 | D19: 6 | E19: 1 | F19: 2 | G19: 17 | H19: =SUM(B19:G19) -> 35
A20: （参考）長期玉 | B20: 0 | C20: 0 | D20: 0 | E20: 0 | F20: 0 | G20: 300 | H20: =SUM(B20:G20) -> 300
A22: ※ 必要転換率が100%を超える月は、いまある玉では月予算に届かないことを意味します。
A23: ※ 長期玉はCD玉に含めていません。

Sheet 月次増減
A1: 9月の増減（2026/09/01 → 09/28） 単位：千円
A2: SFの商談変更履歴405件を再生して復元。9/29・9/30の動きは含まれていません。
A4: ■ グループ別
A5: グループ | C5: AB総玉 増減 | D5: 総玉 増減 | E5: メモ
A6: コーデ+TREEBATON | C6: 13842 | D6: 13815 | E6: 確度UP2件で+10,616
A7: 建築 | C7: 462 | D7: 462 | E7: 枠材製作モックアップの新規のみ
A8: OEM | C8: 0 | D8: 16000 | E8: アースボートは確度Dのまま金額だけ増加
A9: その他 | C9: -2300 | D9: -2500 | E9: FM_フルサポートが来期へ期ズレ
A10: 全社合計 | C10: =SUM(C6:C9) -> 12004 | D10: =SUM(D6:D9) -> 27777
A12: ■ 理由カテゴリ別（AB総玉への影響）
A13: カテゴリ | B13: 件数 | C13: AB総玉 増減 | E13: メモ
A14: 確度UP | B14: 6 | C14: 11896 | E14: うち認証桧柾目材供給PJ 2件で10,616（89%）
A15: 新規作成 | B15: 12 | C15: 2391 | E15: 新規38件のうちAB玉に乗ったのは12件だけ
A16: 失注から復活 | B16: 1 | C16: 220 | E16: 習志野カントリークラブ_VIPルーム黒柿
A17: 増額 | B17: 1 | C17: 47 | E17: 新潟県新潟市石山PJ
A18: 減額 | B18: 2 | C18: -50
A19: 期ズレ（来期へ） | B19: 1 | C19: -2500 | E19: FM_フルサポート_SLIMF
A20: 合計 | B20: =SUM(B14:B19) -> 23 | C20: =SUM(C14:C19) -> 12004
A21: 項目 | B21: 件数 | C21: 金額 | E21: メモ
A22: 9月の成約 | B22: 14 | C22: 17383 | E22: 千本松牧場PJ関連4件で9,334（54%）
A23: 9月の新規作成 | B23: 38 | C23: 9345 | E23: うち18件が金額未入力
A24: 9月の失注 | B24: 10 | C24: -5597 | E24: すべて確度C・D。AB総玉への影響なし
A26: ■ 案件別の明細（AB総玉が動いたもの）
A27: グループ | B27: 商談名 | C27: AB総玉 増減 | D27: 理由 | E27: メモ
A28: コーデ+TREEBATON | B28: 子商談_認証桧柾目材供給PJ_3回目(FSC尾鷲) | C28: 7616 | D28: 確度UP（C→B）／増額
A29: コーデ+TREEBATON | B29: 子商談_認証桧柾目材供給PJ_2回目(SGEC富士市) | C29: 3000 | D29: 確度UP（C→A）／減額
A30: コーデ+TREEBATON | B30: ERIKOYAMAGUCHI_名古屋 | C30: 1128 | D30: 新規
A31: コーデ+TREEBATON | B31: 御殿場KEEN店舗_カウンター用静岡県産半割丸太 | C31: 500 | D31: 確度UP（C→B）
A32: 建築 | B32: 枠材製作（材工）モックアップ製作 | C32: 462 | D32: 新規
A33: コーデ+TREEBATON | B33: TREホールディングス_丸太輪切り材 | C33: 430 | D33: 確度UP（C→A）／増額
A34: コーデ+TREEBATON | B34: 習志野カントリークラブ_VIPルーム黒柿 | C34: 220 | D34: 失注から復活／確度UP（D→B）／減額
A35: その他 | B35: 維持審査_加工_紙 | C35: 200 | D35: 確度UP（D→B）
A36: コーデ+TREEBATON | B36: 水戸京成RLC | C36: 173 | D36: 新規
A37: コーデ+TREEBATON | B37: ロイヤルHD本社工場直販店(福岡)_既存樹活用（引上げ・製材・乾燥） | C37: 150 | D37: 確度UP（C→B）／増額
A38: コーデ+TREEBATON | B38: 内閣府用木札_2026 | C38: 149 | D38: 新規
A39: コーデ+TREEBATON | B39: 外装用焼杉（羽目板） | C39: 120 | D39: 新規
... A50: その他 | B50: FM_フルサポート_SLIMF | C50: -2500 | D50: 期ズレ（来期へ）

Sheet 算出方法
A1: 算出方法と注意点
A3: ■ データの範囲
A4: 対象 | B4: 商談レコードタイプ＝木材コーディネート＋TREEBATON
A5: 除外 | B5: フェーズ00_失注、テスト商談、＊原価管理用＊
A6: 期間 | B6: 完了予定日が26年度。下期＝2026年10月〜2027年3月
A7: 基準日 | B7: 2026/10/05 SF出力（9月の増減は 09/01〜09/28 の変更履歴）
A8: 含まないもの | B8: OEM・建築。営業3分類の全体を見る場合は別途レポートが必要
A10: ■ 各数字の作り方
A11: ① 受注済 | B11: 下期・フェーズ「07.成約」の金額合計（8件 13,111千円）
A12: ② AB玉 | B12: 下期・確度A または B・フェーズ07以外の金額合計（12件 20,739千円）
A13: ③ CD玉 | B13: 下期・確度C または D・フェーズ07以外の金額合計（113件 183,799千円）
A14: AB玉ベース着地見込み | B14: ① ＋ ②。確度が高く、ほぼ動かない確定ライン
A15: 残り必要額 | B15: 下期予算 −（①＋②）
A16: 必要転換率 | B16: 残り必要額 ÷ CD玉。CD玉のうちこれだけ成約できれば予算に届く
A17: 想定転換率 37.3% | B17: スプレッドシート（直近2年593件）の実測成約率。成約件数 ÷ 総商談件数
A18: 最終着地見込み | B18: ① ＋ ② ＋（CD玉 × 想定転換率）
A19: 月予算 | B19: 下期予算 ÷ 6ヶ月の均等割。実際の月次配分があれば月次シートで直接上書きする
A21: ■ 9月増減の作り方
A22: 方法 | B22: SFの商談変更履歴（確度2・金額・フェーズ・完了予定日・作成）405件を時系列で再生
A23: 9/1時点の値 | B23: 現在値から変更チェーンを逆向きに辿って復元
A24: AB総玉の定義 | B24: 確度A・B かつ フェーズ≠00_失注 かつ 完了予定日が26年度内 の金額
A26: ■ 注意点
A27: 下期予算 141,913千円 | B27: 9/11時点で使用した値。SFの正式な下期予算と一致するか要確認。ここが変わると全部動く
A28: 金額未入力 | B28: 下期CD玉113件のうち34件（30%）が空欄。CD玉183,799千円は過小評価
A29: 3月への集中 | B29: 下期CD玉の65%（118,674千円・52件）が3月完了予定
A30: 保有の偏り | B30: CD玉の81%（62件 148,987千円）を片岡さんが保有
A31: 11月の薄さ | B31: 玉が9件・9,820千円。AB玉は阪急阪神不動産3,700の1件のみ
A32: 9月の集中 | B32: AB総玉増加の99%が確度UP。うち89%が認証桧柾目材供給PJの2件
