Workbook

Sheet 週次サマリー
B2: 営業 週次報告
B3: ="対象月 "&入力!B5&" ／ 比較： "&入力!B14&" → "&入力!B15&" ／ 単位：千円 ／ 経過 "&入力!B10&" / "&入力!B9&" 営業日"
B5: １．今週のハイライト
B6: 1〜2文。数字の根拠は②以降に置く。
B7: 【要記入】
B11: ２．数字サマリー
B12: 目標・実績・先週比・進捗率。必要進捗率は 経過営業日 ÷ 当月営業日 です。
B13: AB昇格額（正味）実績 | E13: 月次目標 | H13: 進捗率 | K13: 先週比
B14: =入力!C19 | E14: =入力!B6 | H14: =IFERROR(入力!C19/入力!B6,0) | K14: =入力!D19
B15: 当月完了予定分 | E15: 13,369千円 | H15: 実績 ÷ 目標 | K15: 当月分の増減
B17: 商談獲得 有効件数 | E17: 月次目標 | H17: 進捗率 | K17: 先週比
B18: =入力!C27 | E18: =入力!B7 | H18: =IFERROR(入力!C27/入力!B7,0) | K18: =入力!D27
B19: 当月完了予定分 | E19: 23件 | H19: 実績 ÷ 目標 | K19: 当月分の増減
B21: 商談発生額 実績 | E21: 月次目標 | H21: 進捗率 | K21: 先週比
B22: =入力!C35 | E22: =入力!B8 | H22: =IFERROR(入力!C35/入力!B8,0) | K22: =入力!D35
B23: 当月完了予定分 | E23: 69,000千円 | H23: 実績 ÷ 目標 | K23: 当月分の増減
B25: 必要進捗率（今週時点） | E25: AB昇格額の過不足 | H25: 商談件数の過不足 | K25: 商談発生額の過不足
B26: =入力!B11 | E26: =IFERROR(入力!C19/入力!B6,0)-入力!B11 | H26: =IFERROR(入力!C27/入力!B7,0)-入力!B11 | K26: =IFERROR(入力!C35/入力!B8,0)-入力!B11
B27: 経過営業日 ÷ 当月営業日 | E27: 進捗率 − 必要進捗率 | H27: 進捗率 − 必要進捗率 | K27: 進捗率 − 必要進捗率
B44: 玉の増減（先週 → 今週）
B45: AB玉 残高 | E45: CD玉 残高 | H45: 総玉 残高 | K45: 商談件数
B46: =入力!C43 | E46: =入力!C44 | H46: =入力!C45 | K46: =入力!C46
B47: ="先週比 "&TEXT(入力!D43,"+#,##0;-#,##0;0") | E47: ="先週比 "&TEXT(入力!D44,"+#,##0;-#,##0;0") | H47: ="先週比 "&TEXT(入力!D45,"+#,##0;-#,##0;0") | K47: ="先週比 "&TEXT(入力!D46,"+#,##0;-#,##0;0")&"件"
B49: ３．時期別の内訳
B50: 当月・来月以降・来期のどこに積み上がっているか。完了予定日が未入力の商談は進捗率の分子から漏れます。
B51: AB昇格額｜当月 | D51: 来月以降（今期） | F51: 来期 | H51: 完了日 未入力 | J51: 合計
B52: =入力!C19 | D52: =入力!C20 | F52: =入力!C21 | H52: =入力!C22 | J52: =入力!C23
B53: ="先週比 "&TEXT(入力!D19,"+#,##0;-#,##0;0") | D53: ="先週比 "&TEXT(入力!D20,"+#,##0;-#,##0;0") | F53: ="先週比 "&TEXT(入力!D21,"+#,##0;-#,##0;0") | H53: ="先週比 "&TEXT(入力!D22,"+#,##0;-#,##0;0") | J53: ="先週比 "&TEXT(入力!D23,"+#,##0;-#,##0;0")
B55: 商談発生額｜当月 | D55: 来月以降（今期） | F55: 来期 | H55: 完了日 未入力 | J55: 合計
B56: =入力!C35 | D56: =入力!C36 | F56: =入力!C37 | H56: =入力!C38 | J56: =入力!C39
B57: ="先週比 "&TEXT(入力!D35,"+#,##0;-#,##0;0") | D57: ="先週比 "&TEXT(入力!D36,"+#,##0;-#,##0;0") | F57: ="先週比 "&TEXT(入力!D37,"+#,##0;-#,##0;0") | H57: ="先週比 "&TEXT(入力!D38,"+#,##0;-#,##0;0") | J57: ="先週比 "&TEXT(入力!D39,"+#,##0;-#,##0;0")
B89: 完了予定日 未入力 件数 | E89: 同 金額 | H89: 商談獲得｜当月 件数 | K89: 商談獲得｜合計 件数
B90: =入力!C50 | E90: =入力!C51 | H90: =入力!C27 | K90: =入力!C31
B91: ="先週比 "&TEXT(入力!D50,"+#,##0;-#,##0;0")&"件" | E91: ="先週比 "&TEXT(入力!D51,"+#,##0;-#,##0;0") | H91: ="先週比 "&TEXT(入力!D27,"+#,##0;-#,##0;0")&"件" | K91: ="先週比 "&TEXT(入力!D31,"+#,##0;-#,##0;0")&"件"
B93: 完了予定日が未入力の商談は、当月・来月以降・来期のどれにも入らないため、目標に対する進捗率の分子から漏れます。
B95: ４．その他トピック
B96: 数字に出ない動き。受注・失注の理由、顧客の反応など。
B97: 【要記入】
B102: ５．課題・懸念事項
B103: 来週以降の数字を落としかねないもの。
...

Sheet 入力
A1: 入力シート（青字だけ埋めてください）
A2: 2本のSFレポート（先週分・最新分）から集計した値を入れます。ほかのシートは全部ここから自動計算されます。単位：千円。
A4: ■ A. 当月の目標と営業日
A5: 対象月 | B5: 2026年10月 | C5: ※ レポートの対象月
A6: AB昇格額（正味）目標 | B6: 13369 | C6: ※ 月次目標。正味＝昇格 − 降格
A7: 商談獲得 有効件数 目標 | B7: 23 | C7: ※ 月次目標
A8: 商談発生額 目標 | B8: 69000 | C8: ※ 月次目標
A9: 当月の営業日数 | B9: 21 | C9: ※ 祝日を除いた日数
A10: 経過営業日数（報告時点） | B10: 7 | C10: ※ 報告日までに経過した営業日数
A11: 週次の必要進捗率 | B11: =IFERROR(B10/B9,0) | C11: ＝ 経過営業日数 ÷ 当月の営業日数。この率を実績の進捗率が下回っていたら遅れです
A13: ■ B. 比較する2本のSFレポート
A14: 先週レポートの日付 | B14: 【要記入】 | C14: ※ 例：2026/10/03
A15: 最新レポートの日付 | B15: 【要記入】 | C15: ※ 例：2026/10/10
A17: ■ C. AB昇格額（正味）千円 | C17: 完了予定日がいつの商談か別に。正味＝当週の昇格 − 降格。
A18: 区分 | B18: 先週 | C18: 今週 | D18: 増減
A19: 当月（対象月） | B19: 【要記入】 | C19: 【要記入】 | D19: =IFERROR(C19-B19,0)
A20: 来月以降（今期内） | B20: 【要記入】 | C20: 【要記入】 | D20: =IFERROR(C20-B20,0)
A21: 来期（27年度以降） | B21: 【要記入】 | C21: 【要記入】 | D21: =IFERROR(C21-B21,0)
A22: 完了予定日 未入力 | B22: 【要記入】 | C22: 【要記入】 | D22: =IFERROR(C22-B22,0)
A23: 合計 | B23: =SUM(B19:B22) | C23: =SUM(C19:C22) | D23: =SUM(D19:D22)
A25: ■ D. 商談獲得 有効件数 | C25: 「有効」の定義は算出方法シートに明記してください。
A26: 区分 | B26: 先週 | C26: 今週 | D26: 増減
A27: 当月（対象月） | B27: 【要記入】 | C27: 【要記入】 | D27: =IFERROR(C27-B27,0)
A28: 来月以降（今期内） | B28: 【要記入】 | C28: 【要記入】 | D28: =IFERROR(C28-B28,0)
A29: 来期（27年度以降） | B29: 【要記入】 | C29: 【要記入】 | D29: =IFERROR(C29-B29,0)
A30: 完了予定日 未入力 | B30: 【要記入】 | C30: 【要記入】 | D30: =IFERROR(C30-B30,0)
A31: 合計 | B31: =SUM(B27:B30) | C31: =SUM(C27:C30) | D31: =SUM(D27:D30)
A33: ■ E. 商談発生額 千円 | C33: 新規に発生した商談の金額。完了予定日の時期別に。
A34: 区分 | B34: 先週 | C34: 今週 | D34: 増減
A35: 当月（対象月） | B35: 【要記入】 | C35: 【要記入】 | D35: =IFERROR(C35-B35,0)
A36: 来月以降（今期内） | B36: 【要記入】 | C36: 【要記入】 | D36: =IFERROR(C36-B36,0)
A37: 来期（27年度以降） | B37: 【要記入】 | C37: 【要記入】 | D37: =IFERROR(C37-B37,0)
A38: 完了予定日 未入力 | B38: 【要記入】 | C38: 【要記入】 | D38: =IFERROR(C38-B38,0)
A39: 合計 | B39: =SUM(B35:B38) | C39: =SUM(C35:C38) | D39: =SUM(D35:D38)
A41: ■ F. 玉の残高（参考）
A42: 区分 | B42: 先週 | C42: 今週 | D42: 増減
A43: AB玉 残高 | B43: 【要記入】 | C43: 【要記入】 | D43: =IFERROR(C43-B43,0)
A44: CD玉 残高 | B44: 【要記入】 | C44: 【要記入】 | D44: =IFERROR(C44-B44,0)
A45: 総玉 残高 | B45: 【要記入】 | C45: 【要記入】 | D45: =IFERROR(C45-B45,0)
A46: 商談件数（総数） | B46: 【要記入】 | C46: 【要記入】 | D46: =IFERROR(C46-B46,0)
...

Sheet グラフ用データ
A1: グラフ用データ（週次サマリーのグラフが参照します）
A2: すべて入力シートからの自動計算。
A4: 指標 | B4: 進捗率 | C4: 必要進捗率
A5: AB昇格額（正味） | B5: =IFERROR(入力!C19/入力!B6,0) | C5: =入力!B11
A6: 商談獲得 有効件数 | B6: =IFERROR(入力!C27/入力!B7,0) | C6: =入力!B11
A7: 商談発生額 | B7: =IFERROR(入力!C35/入力!B8,0) | C7: =入力!B11
A9: AB昇格額（正味）の時期別
A10: 区分 | B10: 当月（対象月） | C10: 来月以降（今期内） | D10: 来期（27年度以降） | E10: 完了予定日 未入力
A11: 先週 | B11: =入力!B19 | C11: =入力!B20 | D11: =入力!B21 | E11: =入力!B22
A12: 今週 | B12: =入力!C19 | C12: =入力!C20 | D12: =入力!C21 | E12: =入力!C22
A14: 商談発生額の時期別
A15: 区分 | B15: 当月（対象月） | C15: 来月以降（今期内） | D15: 来期（27年度以降） | E15: 完了予定日 未入力
A16: 先週 | B16: =入力!B35 | C16: =入力!B36 | D16: =入力!B37 | E16: =入力!B38
A17: 今週 | B17: =入力!C35 | C17: =入力!C36 | D17: =入力!C37 | E17: =入力!C38

Sheet 算出方法
A1: 算出方法と定義
A3: ■ 使うレポート
A4: 先週分 | B4: 【要記入】レポート名と出力日時
A5: 最新分 | B5: 【要記入】レポート名と出力日時
A6: 抽出条件 | B6: 【要記入】レコードタイプ・除外条件（失注／テスト商談／＊原価管理用＊ など）
A8: ■ 時期の区分
A9: 当月（対象月） | B9: 完了予定日が対象月のもの。月次目標に対する進捗の分子はここ
A10: 来月以降（今期内） | B10: 完了予定日が翌月〜今期末（2027/03/31）のもの
A11: 来期（27年度以降） | B11: 完了予定日が2027/04/01以降のもの
A12: 完了予定日 未入力 | B12: 完了予定日が空欄。どの区分にも入らず、進捗率の分子から漏れる
A14: ■ 指標の定義
A15: AB昇格額（正味） | B15: 当週に確度C・D・長期から A・B へ上がった金額 − 逆に下がった金額
A16: 商談獲得 有効件数 | B16: 【要記入】「有効」の定義を明記（例：確度が付いている／金額が入っている など）
A17: 商談発生額 | B17: 当週に新規発生した商談の金額
A18: 必要進捗率 | B18: 経過営業日数 ÷ 当月の営業日数。実績の進捗率がこれを下回っていたら遅れ
A19: 過不足 | B19: 進捗率 − 必要進捗率。マイナスなら遅れ
A21: ■ 月次目標
A22: AB昇格額（正味） | B22: 13,369千円／月
A23: 商談獲得 有効件数 | B23: 23件／月
A24: 商談発生額 | B24: 69,000千円／月
A26: ■ 配色
A27: カテゴリ配色 | B27: 2E8B57／E09B22／3B7DD8／C0453E／8E5BC4。色覚多様性を検証済み（CVD分離 ΔE 12.9）
A28: 見出し・強調 | B28: 2C5F2D（森）／C87941（注意）／B04A3C（警告）
B29: ※ 社内のブランドガイドラインがあれば差し替えてください
